Workbook
Name adv: [1]Exp.PaymentTerms!$E$12
Name hand: [1]Exp.PaymentTerms!$G$12

Sheet СравнениеPnl 
B1: Без перегородок | C1: С перегородками
A2: Реализуемая площадь, м2 | B2: =SUM(B3:B6) -> 6901 | C2: =SUM(C3:C6) -> 17982.736 | D2: =C2-B2 -> 11081.736
A3: Квартиры (себес м2 * площадь) | B3: ='Dashboard все'!L16 -> 0 | C3: ='PnL (с перегор)'!B8 -> 11081.736 | D3: =C3-B3 -> 11081.736
A4: Коммерческие помещения | B4: ='Dashboard все'!L17 -> 6232 | C4: ='PnL (с перегор)'!B9 -> 6232 | D4: =C4-B4 -> 0
A5: Кладовые помещения | B5: ='Dashboard все'!L18 -> 253 | C5: ='PnL (с перегор)'!B10 -> 253 | D5: =C5-B5 -> 0
A6: Паркинги | B6: ='Dashboard все'!L19 -> 416 | C6: ='PnL (с перегор)'!B11 -> 416 | D6: =C6-B6 -> 0
A7: Реализуемое количество, шт | B7: =SUM(B8:B11) -> 50 | C7: =SUM(C8:C11) -> 469 | D7: =C7-B7 -> 419
A8: Квартиры (себес м2 * площадь) | B8: ='Dashboard все'!L23 -> 0 | C8: ='Dashboard (с перегор)'!L23 -> 240 | D8: =C8-B8 -> 240
A9: Коммерческие помещения | B9: ='Dashboard все'!L24 -> 22 | C9: ='Dashboard (с перегор)'!L24 -> 0 | D9: =C9-B9 -> -22
A10: Кладовые помещения | B10: ='Dashboard все'!L25 -> 2 | C10: ='Dashboard (с перегор)'!L25 -> 153 | D10: =C10-B10 -> 151
A11: Паркинги | B11: ='Dashboard все'!L26 -> 26 | C11: ='Dashboard (с перегор)'!L26 -> 76 | D11: =C11-B11 -> 50
A12: Средние цены реализации: | B12: =B22/B2 -> 1552427.2 | C12: =C22/C2 -> 428025.99 | D12: =C12-B12 -> -1124401.2
A13: Квартиры (себес м2 * площадь) | B13: ='Dashboard все'!F16 -> 0 | C13: ='Dashboard (с перегор)'!F16 -> 650000 | D13: =C13-B13 -> 650000
A14: Коммерческие помещения | B14: ='Dashboard все'!F17 -> 1600000 | C14: ='Dashboard (с перегор)'!F17 -> 0 | D14: =C14-B14 -> -1600000
A15: Кладовые помещения | B15: ='Dashboard все'!F18 -> 1700000 | C15: ='Dashboard (с перегор)'!F18 -> 150000 | D15: =C15-B15 -> -1550000
A16: Паркинги | B16: ='Dashboard все'!F19 -> 12000000 | C16: ='Dashboard (с перегор)'!F19 -> 6000000 | D16: =C16-B16 -> -6000000
A17: Cебестоимость СМР за м2: | B17: =(B29)/(B3+B4+B5+B6) -> 665927.82 | C17: =(C29)/(C3+720+C4+C5+C6) -> 665927.82 | D17: =C17-B17 -> 0
A18: Квартиры (себес м2 * площадь) | B18: ='Dashboard все'!I16 -> 665927.82 | C18: ='Dashboard (с перегор)'!I16 -> 285417.25 | D18: =C18-B18 -> -380510.57
A19: Коммерческие помещения | B19: 0 | C19: 0 | D19: =C19-B19 -> 0
A20: Кладовые помещения | B20: 0 | C20: 0 | D20: =C20-B20 -> 0
A21: Паркинги | D21: =C21-B21 -> 0
A22: Выручка итого в т.ч. | B22: =SUM(B23:B26) -> 10713300000 | C22: =SUM(C23:C26) -> 7.6970782e+09 | D22: =C22-B22 -> -3.0162218e+09
A23: Квартиры (себес м2 * площадь) | B23: =(B3*B13) -> 0 | C23: =(C3*C13) -> 7.2031282e+09 | D23: =C23-B23 -> 7.2031282e+09
A24: Коммерческие помещения | B24: =(B4*B14) -> 9971200000 | C24: =(C4*C14) -> 0 | D24: =C24-B24 -> -9971200000
A25: Кладовые помещения | B25: =(B5*B15) -> 430100000 | C25: =(C5*C15) -> 37950000 | D25: =C25-B25 -> -392150000
A26: Паркинги | B26: =(B11*B16) -> 312000000 | C26: =(C11*C16) -> 456000000 | D26: =C26-B26 -> 144000000
A27: Расходы итого: | B27: =B28+B30+B32+B34+B39+B41 -> 7.505397e+09 | C27: =C28+C30+C32+C34+C39+C41 -> #REF! | D27: =C27-B27 -> #REF!
A28: СМР в т.ч.: | B28: =SUM(B29:B29) -> 4595567890 | C28: =SUM(C29:C29) -> 1.2454672e+10 | D28: =C28-B28 -> 7.8591041e+09
A29: СМР(себес м2 * площадь) | B29: =B2*B18 -> 4595567890 | C29: ='PnL (с перегор)'!B41 -> 1.2454672e+10 | D29: =C29-B29 -> 7.8591041e+09
A30: ЗУ в т.ч.: | B30: =B31 -> 675000000 | C30: =C31 -> 675000000 | D30: =C30-B30 -> 0
A31: Земельный участок | B31: ='PnL все'!B49 -> 675000000 | C31: ='PnL (с перегор)'!B49 -> 675000000 | D31: =C31-B31 -> 0
A32: ПИР в т.ч.: | B32: =SUM(B33:B33) -> 197152741 | C32: =SUM(C33:C33) -> 5.3431323e+08 | D32: =C32-B32 -> 3.3716049e+08
A33: ПИР, тг | B33: ='PnL все'!B51 -> 197152741 | C33: ='PnL (с перегор)'!B51 -> 5.3431323e+08 | D33: =C33-B33 -> 3.3716049e+08
A34: Накладные расходы вт.ч. | B34: =SUM(B35:B38) -> 1.2377462e+09 | C34: =SUM(C35:C38) -> 1.8506659e+09 | D34: =C34-B34 -> 6.1291969e+08
A35: Накладные расходы, тг | B35: ='PnL все'!B53 -> 447216142 | C35: ='PnL (с перегор)'!B53 -> 1.2120222e+09 | D35: =C35-B35 -> 7.6480607e+08
A36: Административные расходы проекта, 1% | B36: ='PnL все'!B54 -> 45955679 | C36: ='PnL (с перегор)'!B54 -> 1.2454672e+08 | D36: =C36-B36 -> 78591041
A37: Содержание HCG (11+6 этаж), 2,4% | B37: ='PnL все'!B58 -> 257119200 | C37: ='PnL (с перегор)'!B58 -> 1.7752988e+08 | D37: =C37-B37 -> -79589324
A38: Расходы на реализацию, тг 4,55% | B38: ='PnL все'!B61 -> 487455150 | C38: ='PnL (с перегор)'!B61 -> 3.3656706e+08 | D38: =C38-B38 -> -1.5088809e+08
A39: % по кредиту | B39: =SUM(B40:B40) -> 112218750 | C39: =SUM(C40:C40) -> 112218750 | D39: =C39-B39 -> 0
A40: % по кредиту | B40: ='PnL все'!B66 -> 112218750 | C40: ='PnL (с перегор)'!B66 -> 112218750 | D40: =C40-B40 -> 0
...

Sheet Сравнение
B1: Цена | C1: ='Dashboard все'!F16 -> 0 | D1: ='Dashboard (с перегор)'!F16 -> 650000
B2: Korkem | C2: Без перегородок | D2: С перегородками | E2: Отклонение
B3: Выручка | C3: ='PnL все'!B34 -> 10713300000 | D3: ='PnL (с перегор)'!B34 -> 7.3970782e+09 | E3: =D3-C3 -> -3.3162218e+09
B4: ЗУ | C4: ='PnL все'!B48 -> 675000000 | D4: ='PnL (с перегор)'!B48 -> 675000000 | E4: =D4-C4 -> 0
B5: СМР | C5: ='PnL все'!B40 -> 4595567890 | D5: ='PnL (с перегор)'!B40 -> 1.2454672e+10 | E5: =D5-C5 -> 7.8591041e+09
B6: Накладные+ПИР | C6: ='PnL все'!B53+'PnL все'!B50 -> 644368883 | D6: ='PnL (с перегор)'!B50+'PnL (с перегор)'!B53 -> 1.7463354e+09 | E6: =D6-C6 -> 1.1019666e+09
B7: РР | C7: ='PnL все'!B61 -> 487455150 | D7: ='PnL (с перегор)'!B61 -> 3.3656706e+08 | E7: =D7-C7 -> -1.5088809e+08
B8: HO | C8: ='PnL все'!B58 -> 257119200 | D8: ='PnL (с перегор)'!B58 -> 1.7752988e+08 | E8: =D8-C8 -> -79589324
B9: Адм.расходы | C9: ='PnL все'!B54 -> 45955679 | D9: ='PnL (с перегор)'!B54 -> 1.2454672e+08 | E9: =D9-C9 -> 78591041
B10: Кредит,%% | C10: ='PnL все'!B66 -> 112218750 | D10: ='PnL (с перегор)'!B66 -> 112218750 | E10: =D10-C10 -> 0
B11: Налоги(НДС, КПН) | C11: ='PnL все'!B70+'PnL все'!B73 -> 1.3292921e+09 | D11: ='PnL (с перегор)'!B70+'PnL (с перегор)'!B73 -> #REF! | E11: =D11-C11 -> #REF!
B12: ЧП | C12: =C3-C4-C5-C6-C7-C8-C9-C10-C11 -> 2.5663224e+09 | D12: =D3-D4-D5-D6-D7-D8-D9-D10-D11 -> #REF! | E12: =D12-C12 -> #REF!
B13: Рентабельность | C13: =C12/C3 -> 0.23954546 | D13: =D12/D3 -> #REF! | E13: =D13-C13 -> #REF!

Sheet Сравнительная
A2: Итоговые показатели | B2: все этажи | C2: 2-8 этажи | D2: Откл.
A3: Revenue | B3: ='PnL все'!B34 -> 10713300000 | C3: ='PnL2-8'!B34 -> 8049600000 | D3: =B3-C3 -> 2663700000
A4: Net Profit | B4: ='Dashboard все'!C4 -> 2.5663224e+09 | C4: ='Dashboard2-8'!C4 -> 9.488255e+08 | D4: =B4-C4 -> 1.6174969e+09
A5: ROS, % | B5: =B4/B3 -> 0.23954546 | C5: =C4/C3 -> 0.11787238 | D5: =B5-C5 -> 0.12167308
A6: NPV | B6: ='Dashboard все'!C9 -> 1.8777444e+09 | C6: ='Dashboard2-8'!C9 -> 9.7260965e+08 | D6: =B6-C6 -> 9.0513475e+08

Sheet Dashboard все
B3: Итоговые показатели
B4: Net Profit | C4: ='PnL все'!B74 -> 2.5663224e+09
B5: ROS, % | C5: ='PnL все'!B75 -> 0.23954546
B6: ROE (Отдача на капитал) | C6: =DCF!C44 -> 0
B7: WACC (Годовой) | C7: =DCF!C47*12 -> 0.21
B8: IRR (Минимальная ставка доходности) | C8: =DCF!C41 -> 15.142248
B9: NPV | C9: =DCF!C42 -> 1.8777444e+09
B10: PP | C10: =DCF!C37 -> 1
B11: DPP | C11: =DCF!C46 -> 1
B14: Основные вводные
B15: LAND | E15: SALES | H15: COSTS | K15: Sellable Area, sq.m | L15: =SUM(L16:L19) -> 6901
B16: Площадь ЗУ, га | C16: 0.15 | E16: Цена за м2 квартиры | F16: 0 | H16: Себестоимость за м2 | I16: =(4550567890+45000000)/L15 -> 665927.82 | K16: Квартиры | L16: 0 | N16: =N17/L17 -> 0.22400513
B17: Курс ЗУ | C17: 500 | E17: Цена за м2 офиса | F17: 1600000 | H17: Накладные расходы | I17: =447216142/L15 -> 64804.542 | K17: Офисы | L17: 6232 | M17: 4836 | N17: =L17-M17 -> 1396 | O17: =F17 -> 1600000 | P17: =N17*O17 -> 2233600000
B18: Стоимость за сотку, USD | C18: 90000 | E18: Цена за м2 коммерция | F18: 1700000 | H18: Расходы на реализацию | I18: 0.0455 | K18: Коммерция | L18: 253 | M18: 0 | N18: =L18-M18 -> 253 | O18: =F18 -> 1700000 | P18: =N18*O18 -> 430100000
B19: Стоимость участка итого, KZT | C19: =C16*100*C18*C17 -> 675000000 | E19: Цена за 1 м/м | F19: 12000000 | H19: Расходы офиса | I19: 0.024 | K19: Паркинг | L19: =L26*16 -> 416 | M19: 416
H20: ПИРы | I20: =197152741/L15 -> 28568.721
B22: CONSTRUCTION | E22: CASH FLOW | H22: TAXES | K22: Sellable Units, pcs | L22: =SUM(L23:L26) -> 50
B23: Этажность | C23: 10 | E23: Собственный капитал | H23: НДС | I23: ='PnL все'!B70 -> 6.8771146e+08 | K23: Квартиры | L23: 0
B24: Застраиваемая площадь | E24: Кредит | F24: =C19 -> 675000000 | H24: КПН | I24: ='PnL все'!B73 -> 6.415806e+08 | K24: Офисы | L24: 22
B25: Продаваемая площадь | C25: ='PnL все'!B7 -> 6901 | E25: Срок займа, мес | F25: 18 | K25: Коммерция | L25: 2
B26: Прод площ 1 очереди | C26: =C25 -> 6901 | E26: Дивиденды | F26: ='PnL все'!B74 -> 2.5663224e+09 | K26: Паркинг | L26: 26
E27: Дата займа | F27: 46204
B28: ЖЦП, мес | C28: 18 | E28: Ставка, % | F28: 21
B29: Дата старта | C29: 46204 | E29: Льготный период, мес | F29: 0
I32: 4.5505679e+09
B34: Собственный капитал | C34: 0
B35: Ставка займа (годовая) | C35: 0.21
B36: Стоимость акционерских денег | C36: 0.25

Sheet PnL все
A2: Показатель | B2: KZT | C2: USD
A3: Цена за сотку (Общая), USD | B3: =B48/B5/100/B4 -> 90000
A4: Курс $ | B4: ='Dashboard все'!C17 -> 500
A5: Земельный участок га | B5: ='Dashboard все'!C16 -> 0.15
A6: Этажность | B6: ='Dashboard все'!C23 -> 10
A7: Реализуемая площадь, м2 | B7: =SUM(B8:B11) -> 6901 | C7: =SUM(C8:C11) -> 6901
A8: Квартиры (себес м2 * площадь) | B8: ='Dashboard все'!L16 -> 0 | C8: =B8 -> 0
A9: Коммерческие помещения | B9: ='Dashboard все'!L17 -> 6232 | C9: =B9 -> 6232
A10: Коммерция | B10: ='Dashboard все'!L18 -> 253 | C10: =B10 -> 253
A11: Паркинги | B11: ='Dashboard все'!L19 -> 416 | C11: =B11 -> 416
A12: Реализуемое количество, шт | B12: =SUM(B13:B16) -> 50 | C12: =SUM(C13:C16) -> 50
A13: Квартиры (себес м2 * площадь) | B13: ='Dashboard все'!L23 -> 0 | C13: =B13 -> 0
A14: Офисы | B14: ='Dashboard все'!L24 -> 22 | C14: =B14 -> 22
A15: Коммерция | B15: 2 | C15: =B15 -> 2
A16: Паркинги | B16: ='Dashboard все'!L26 -> 26 | C16: =B16 -> 26
A17: Средние цены реализации: | B17: =B34/B7 -> 1552427.2 | C17: =C34/C7 -> 3104.8544
A18: Квартиры (себес м2 * площадь) | B18: ='Dashboard все'!F16 -> 0 | C18: =B18/$B$4 -> 0
A19: Офис | B19: ='Dashboard все'!F17 -> 1600000 | C19: =B19/$B$4 -> 3200
A20: Коммерческие помещения | B20: ='Dashboard все'!F18 -> 1700000 | C20: =B20/$B$4 -> 3400
A21: Паркинги | B21: ='Dashboard все'!F19 -> 12000000 | C21: =B21/$B$4 -> 24000
A22: Cебестоимость СМР за м2: | B22: =(B41+B42+B43+B44)/(B8+B9+B10+B11) -> 665927.82 | C22: =B22/$B$4 -> 1331.8556
A23: Квартиры (себес м2 * площадь) | B23: ='Dashboard все'!I16 -> 665927.82 | C23: =B23/$B$4 -> 1331.8556
A24: Коммерческие помещения | B24: 0 | C24: =B24/$B$4 -> 0
A25: Кладовые помещения | B25: 0 | C25: =B25/$B$4 -> 0
A26: Паркинги | B26: 0 | C26: =B26/$B$4 -> 0
A27: Средняя себестоимость (СМР+ПСД+опер.+накл.) | B27: =SUM(B28:B33) -> 971665.96 | C27: =B27/$B$4 -> 1943.3319
A28: Строительно-монтажные работы | B28: =B40/(B8+B9+B10+B11) -> 665927.82 | C28: =B28/$B$4 -> 1331.8556
A29: Земельный участок | B29: =B48/B7 -> 97811.911 | C29: =B29/$B$4 -> 195.62382
A30: Расходы заказчика | B30: =B50/B7 -> 28568.721 | C30: =B30/$B$4 -> 57.137441
A31: Накладные расходы | B31: =B52/B7 -> 179357.51 | C31: =B31/$B$4 -> 358.71502
A32: Социальная нагрузка | B32: 0 | C32: =B32/$B$4 -> 0
A33: % по кредиту | B33: 0 | C33: =B33/$B$4 -> 0
A34: Выручка итого в т.ч. | B34: =SUM(B35:B38) -> 10713300000 | C34: =B34/$B$4 -> 21426600
A35: Квартиры (себес м2 * площадь) | B35: =(B8*B18) -> 0 | C35: =B35/$B$4 -> 0
A36: Офис | B36: =(B9*B19) -> 9971200000 | C36: =B36/$B$4 -> 19942400
A37: Коммерческие помещения | B37: =(B10*B20) -> 430100000 | C37: =B37/$B$4 -> 860200
A38: Паркинги | B38: =(B16*B21) -> 312000000 | C38: =B38/$B$4 -> 624000
A39: Расходы итого: | B39: =B40+B48+B50+B52+B62+B66+B68+B70 -> 7.505397e+09 | C39: =B39/$B$4 -> 15010794
A40: СМР в т.ч.: | B40: =SUM(B41:B47) -> 4595567890 | C40: =B40/$B$4 -> 9191135.8 | F40: =B40/20 -> 2.2977839e+08
A41: СМР(себес м2 * площадь) | B41: =B7*'Dashboard все'!I16 -> 4595567890 | C41: =B41/$B$4 -> 9191135.8
...

Sheet Dashboard2-8
B3: Итоговые показатели
B4: Net Profit | C4: ='PnL2-8'!B74 -> 9.488255e+08
B5: ROS, % | C5: =[2]PnL!B75 -> 0.18947345
B6: ROE (Отдача на капитал) | C6: =[2]DCF!C44 -> 0
B7: WACC (Годовой) | C7: =[2]DCF!C47*12 -> 0.21
B8: IRR (Минимальная ставка доходности) | C8: =[2]DCF!C41 -> 1.7278268
B9: NPV | C9: =[2]DCF!C42 -> 9.7260965e+08
B10: PP | C10: =[2]DCF!C37 -> 1
B11: DPP | C11: =[2]DCF!C46 -> 1
B14: Основные вводные
B15: LAND | E15: SALES | H15: COSTS | K15: Sellable Area, sq.m | L15: =SUM(L16:L19) -> 5252
B16: Площадь ЗУ, га | C16: 0.15 | E16: Цена за м2 квартиры | F16: 0 | H16: Себестоимость за м2 | I16: =(4550567890+45000000)/L15 -> 875012.93 | K16: Квартиры | L16: 0
B17: Курс ЗУ | C17: 500 | E17: Цена за м2 офиса | F17: 1600000 | H17: Накладные расходы | I17: =447216142/L15 -> 85151.588 | K17: Офисы | L17: 4836
B18: Стоимость за сотку, USD | C18: 90000 | E18: Цена за м2 коммерция | H18: Расходы на реализацию | I18: 0.0455 | K18: Коммерция | L18: 0
B19: Стоимость участка итого, KZT | C19: =C16*100*C18*C17 -> 675000000 | E19: Цена за 1 м/м | F19: 12000000 | H19: Расходы офиса | I19: 0.024 | K19: Паркинг | L19: =L26*16 -> 416
H20: ПИРы | I20: =197152741/L15 -> 37538.603
B22: CONSTRUCTION | E22: CASH FLOW | H22: TAXES | K22: Sellable Units, pcs | L22: =SUM(L23:L26) -> 50
B23: Этажность | C23: 10 | E23: Собственный капитал | H23: НДС | I23: =[2]PnL!B70 -> 3.4322847e+08 | K23: Квартиры | L23: 0
B24: Застраиваемая площадь | E24: Кредит | F24: =C19 -> 675000000 | H24: КПН | I24: =[2]PnL!B73 -> 3.8129638e+08 | K24: Офисы | L24: 22
B25: Продаваемая площадь | C25: =[2]PnL!B7 -> 5252 | E25: Срок займа, мес | F25: 18 | K25: Коммерция | L25: 2
B26: Прод площ 1 очереди | C26: =C25 -> 5252 | E26: Дивиденды | F26: =[2]PnL!B74 -> 1.5251855e+09 | K26: Паркинг | L26: 26
E27: Дата займа | F27: 46204
B28: ЖЦП, мес | C28: 18 | E28: Ставка, % | F28: 21
B29: Дата старта | C29: 46204 | E29: Льготный период, мес | F29: 0
I33: 4.5505679e+09
B34: Собственный капитал | C34: 0
B35: Ставка займа (годовая) | C35: 0.21
B36: Стоимость акционерских денег | C36: 0.25

Sheet PnL2-8
A2: Показатель | B2: KZT | C2: USD
A3: Цена за сотку (Общая), USD | B3: =B48/B5/100/B4 -> 90000
A4: Курс $ | B4: =[2]Dashboard!C17 -> 500
A5: Земельный участок га | B5: =[2]Dashboard!C16 -> 0.15
A6: Этажность | B6: =[2]Dashboard!C23 -> 10
A7: Реализуемая площадь, м2 | B7: =SUM(B8:B11) -> 5252 | C7: =SUM(C8:C11) -> 5252
A8: Квартиры (себес м2 * площадь) | B8: =[2]Dashboard!L16 -> 0 | C8: =B8 -> 0
A9: Коммерческие помещения | B9: ='Dashboard2-8'!L17 -> 4836 | C9: =B9 -> 4836
A10: Кладовые помещения | B10: =[2]Dashboard!L18 -> 0 | C10: =B10 -> 0
A11: Паркинги | B11: ='Dashboard2-8'!L19 -> 416 | C11: =B11 -> 416
A12: Реализуемое количество, шт | B12: =SUM(B13:B16) -> 48 | C12: =SUM(C13:C16) -> 48
A13: Квартиры (себес м2 * площадь) | B13: =[2]Dashboard!L23 -> 0 | C13: =B13 -> 0
A14: Коммерческие помещения | B14: ='Dashboard2-8'!L24 -> 22 | C14: =B14 -> 22
A15: Кладовые помещения | C15: =B15 -> 0
A16: Паркинги | B16: ='Dashboard2-8'!L26 -> 26 | C16: =B16 -> 26
A17: Средние цены реализации: | B17: =B34/B7 -> 1532673.3 | C17: =C34/C7 -> 3065.3465
A18: Квартиры (себес м2 * площадь) | B18: =[2]Dashboard!F16 -> 0 | C18: =B18/$B$4 -> 0
A19: Офис | B19: ='Dashboard2-8'!F17 -> 1600000 | C19: =B19/$B$4 -> 3200
A20: Коммерческие помещения | B20: =[2]Dashboard!F18 -> 0 | C20: =B20/$B$4 -> 0
A21: Паркинги | B21: ='Dashboard2-8'!F19 -> 12000000 | C21: =B21/$B$4 -> 24000
A22: Cебестоимость СМР за м2: | B22: =(B41+B42+B43+B44)/(B8+B9+B10+B11) -> 875012.93 | C22: =B22/$B$4 -> 1750.0259
A23: Квартиры (себес м2 * площадь) | B23: ='Dashboard2-8'!I16 -> 875012.93 | C23: =B23/$B$4 -> 1750.0259
A24: Коммерческие помещения | B24: 0 | C24: =B24/$B$4 -> 0
A25: Кладовые помещения | B25: 0 | C25: =B25/$B$4 -> 0
A26: Паркинги | B26: 0 | C26: =B26/$B$4 -> 0
A27: Средняя себестоимость (СМР+ПСД+опер.+накл.) | B27: =SUM(B28:B33) -> 1241496.5 | C27: =B27/$B$4 -> 2482.993
A28: Строительно-монтажные работы | B28: =B40/(B8+B9+B10+B11) -> 875012.93 | C28: =B28/$B$4 -> 1750.0259
A29: Земельный участок | B29: =B48/B7 -> 128522.47 | C29: =B29/$B$4 -> 257.04494
A30: Расходы заказчика | B30: =B50/B7 -> 37538.603 | C30: =B30/$B$4 -> 75.077205
A31: Накладные расходы | B31: =B52/B7 -> 200422.51 | C31: =B31/$B$4 -> 400.84502
A32: Социальная нагрузка | B32: 0 | C32: =B32/$B$4 -> 0
A33: % по кредиту | B33: 0 | C33: =B33/$B$4 -> 0
A34: Выручка итого в т.ч. | B34: =SUM(B35:B38) -> 8049600000 | C34: =B34/$B$4 -> 16099200
A35: Квартиры (себес м2 * площадь) | B35: =(B8*B18) -> 0 | C35: =B35/$B$4 -> 0
A36: Офис | B36: =(B9*B19) -> 7737600000 | C36: =B36/$B$4 -> 15475200
A37: Коммерческие помещения | B37: =(B10*B20) -> 0 | C37: =B37/$B$4 -> 0
A38: Паркинги | B38: =(B16*B21) -> 312000000 | C38: =B38/$B$4 -> 624000
A39: Расходы итого: | B39: =B40+B48+B50+B52+B62+B66+B68+B70 -> 6.8635681e+09 | C39: =B39/$B$4 -> 13727136
A40: СМР в т.ч.: | B40: =SUM(B41:B47) -> 4595567890 | C40: =B40/$B$4 -> 9191135.8
A41: СМР(себес м2 * площадь) | B41: =B7*B23 -> 4595567890 | C41: =B41/$B$4 -> 9191135.8
...

Sheet DCF
D3: =YEAR(D6) -> 2026 | E3: =YEAR(E6) -> 2026 | F3: =YEAR(F6) -> 2026 | G3: =YEAR(G6) -> 2026 | H3: =YEAR(H6) -> 2026 | I3: =YEAR(I6) -> 2026 | J3: =YEAR(J6) -> 2027 | K3: =YEAR(K6) -> 2027 | ... KQ3: =YEAR(KQ6) -> 2051
D4: 1 | E4: =D4+1 -> 2 | F4: =E4+1 -> 3 | G4: =F4+1 -> 4 | H4: =G4+1 -> 5 | I4: =H4+1 -> 6 | J4: =I4+1 -> 7 | K4: =J4+1 -> 8 | L4: =K4+1 -> 9 | ... KQ4: =KP4+1 -> 300
D5: =MONTH(D6) -> 7 | E5: =MONTH(E6) -> 8 | F5: =MONTH(F6) -> 9 | G5: =MONTH(G6) -> 10 | H5: =MONTH(H6) -> 11 | I5: =MONTH(I6) -> 12 | J5: =MONTH(J6) -> 1 | K5: =MONTH(K6) -> 2 | ... KQ5: =MONTH(KQ6) -> 6
B6: Дисконтированные денежные потоки | C6: Total | D6: ='Dashboard все'!C29 -> 46204 | E6: =EDATE(D6,1) -> 46235 | F6: =EDATE(E6,1) -> 46266 | G6: =EDATE(F6,1) -> 46296 | H6: =EDATE(G6,1) -> 46327 | I6: =EDATE(H6,1) -> 46357 | J6: =EDATE(I6,1) -> 46388 | K6: =EDATE(J6,1) -> 46419 | L6: =EDATE(K6,1) -> 46447 | ... KQ6: =EDATE(KP6,1) -> 55305
B7: Поступления по операционной деятельности | C7: =SUM(D7:KQ7) -> 10713300000 | D7: =SUM(D8:D8) -> 321399000 | E7: =SUM(E8:E8) -> 321399000 | F7: =SUM(F8:F8) -> 321399000 | G7: =SUM(G8:G8) -> 321399000 | H7: =SUM(H8:H8) -> 332112300 | I7: =SUM(I8:I8) -> 332112300 | J7: =SUM(J8:J8) -> 332112300 | K7: =SUM(K8:K8) -> 332112300 | ... KQ7: =SUM(KQ8:KQ8) -> 0
B8: Релизация помещений | C8: =SUM(D8:KQ8) -> 10713300000 | D8: =Sales!E15 -> 321399000 | E8: =Sales!F15 -> 321399000 | F8: =Sales!G15 -> 321399000 | G8: =Sales!H15 -> 321399000 | H8: =Sales!I15 -> 332112300 | I8: =Sales!J15 -> 332112300 | J8: =Sales!K15 -> 332112300 | K8: =Sales!L15 -> 332112300 | ... GB8: =Sales!GC15 -> 0 | GC8: =Sales!FU36 -> 0 | GD8: =Sales!FV36 -> 0 | GE8: =Sales!FW36 -> 0 | GF8: =Sales!FX36 -> 0 | GG8: =Sales!FY36 -> 0 | GH8: =Sales!FZ36 -> 0 | GI8: =Sales!GA36 -> 0 | GJ8: =Sales!GB36 -> 0 | ... KQ8: =Sales!KI36 -> 0
B9: Выбытие по операционной деятельности | C9: =SUM(D9:KQ9) -> 5.8333141e+09 | D9: =SUM(D10:D10) -> 2.3333256e+08 | E9: =SUM(E10:E10) -> 2.3333256e+08 | F9: =SUM(F10:F10) -> 2.3333256e+08 | G9: =SUM(G10:G10) -> 2.916657e+08 | H9: =SUM(H10:H10) -> 2.916657e+08 | I9: =SUM(I10:I10) -> 2.916657e+08 | J9: =SUM(J10:J10) -> 2.916657e+08 | K9: =SUM(K10:K10) -> 3.4999884e+08 | ... KQ9: =SUM(KQ10:KQ10) -> 0
B10: Расходы проекта | C10: =SUM(D10:KQ10) -> 5.8333141e+09 | D10: =Costs!E16 -> 2.3333256e+08 | E10: =Costs!F16 -> 2.3333256e+08 | F10: =Costs!G16 -> 2.3333256e+08 | G10: =Costs!H16 -> 2.916657e+08 | H10: =Costs!I16 -> 2.916657e+08 | I10: =Costs!J16 -> 2.916657e+08 | J10: =Costs!K16 -> 2.916657e+08 | K10: =Costs!L16 -> 3.4999884e+08 | ... FU10: =Costs!FV16 -> 0 | FV10: =Costs!FQ37 -> 0 | FW10: =Costs!FR37 -> 0 | FX10: =Costs!FS37 -> 0 | FY10: =Costs!FT37 -> 0 | FZ10: =Costs!FU37 -> 0 | GA10: =Costs!FV37 -> 0 | GB10: =Costs!FW37 -> 0 | GC10: =Costs!FX37 -> 0 | ... KQ10: =Costs!KL37 -> 0
B11: Операционная прибыль EBITDA | C11: =SUM(D11:KQ11) -> 4.8799859e+09 | D11: =D7-D9 -> 88066438 | E11: =E7-E9 -> 88066438 | F11: =F7-F9 -> 88066438 | G11: =G7-G9 -> 29733297 | H11: =H7-H9 -> 40446597 | I11: =I7-I9 -> 40446597 | J11: =J7-J9 -> 40446597 | K11: =K7-K9 -> -17886544 | ... KQ11: =KQ7-KQ9 -> 0
B12: НДС к уплате | C12: =SUM(D12:KQ12) -> 6.8771146e+08 | D12: {=TRANSPOSE(SUMIFS(Графики!$I$7:$I$306,Графики!$D$7:$D$306,DCF!D$6))} -> 0 | E12: {=TRANSPOSE(SUMIFS(Графики!$I$7:$I$306,Графики!$D$7:$D$306,DCF!E$6))} -> 0 | F12: {=TRANSPOSE(SUMIFS(Графики!$I$7:$I$306,Графики!$D$7:$D$306,DCF!F$6))} -> 0 | G12: {=TRANSPOSE(SUMIFS(Графики!$I$7:$I$306,Графики!$D$7:$D$306,DCF!G$6))} -> 0 | H12: {=TRANSPOSE(SUMIFS(Графики!$I$7:$I$306,Графики!$D$7:$D$306,DCF!H$6))} -> 34385573 | I12: {=TRANSPOSE(SUMIFS(Графики!$I$7:$I$306,Графики!$D$7:$D$306,DCF!I$6))} -> 0 | J12: {=TRANSPOSE(SUMIFS(Графики!$I$7:$I$306,Графики!$D$7:$D$306,DCF!J$6))} -> 0 | K12: {=TRANSPOSE(SUMIFS(Графики!$I$7:$I$306,Графики!$D$7:$D$306,DCF!K$6))} -> 34385573 | ... ED12: {=TRANSPOSE(SUMIFS(Графики!$I$7:$I$306,Графики!$D$7:$D$306,DCF!ED$6))} -> 0 | EE12: {=TRANSPOSE(SUMIFS(Графики!$I$7:$I$306,Графики!$D$7:$D$306,DCF!EE6))} -> 0 | EF12: {=TRANSPOSE(SUMIFS(Графики!$I$7:$I$306,Графики!$D$7:$D$306,DCF!EF6))} -> 0 | EG12: {=TRANSPOSE(SUMIFS(Графики!$I$7:$I$306,Графики!$D$7:$D$306,DCF!EG6))} -> 0 | EH12: {=TRANSPOSE(SUMIFS(Графики!$I$7:$I$306,Графики!$D$7:$D$306,DCF!EH6))} -> 0 | EI12: {=TRANSPOSE(SUMIFS(Графики!$I$7:$I$306,Графики!$D$7:$D$306,DCF!EI6))} -> 0 | EJ12: {=TRANSPOSE(SUMIFS(Графики!$I$7:$I$306,Графики!$D$7:$D$306,DCF!EJ6))} -> 0 | EK12: {=TRANSPOSE(SUMIFS(Графики!$I$7:$I$306,Графики!$D$7:$D$306,DCF!EK6))} -> 0 | EL12: {=TRANSPOSE(SUMIFS(Графики!$I$7:$I$306,Графики!$D$7:$D$306,DCF!EL6))} -> 0 | ... KQ12: {=TRANSPOSE(SUMIFS(Графики!$I$7:$I$306,Графики!$D$7:$D$306,DCF!KQ6))} -> 0
B13: КПН | C13: =SUM(D13:KQ13) -> 6.415806e+08 | D13: {=TRANSPOSE(SUMIFS(Графики!$H$7:$H$306,Графики!$D$7:$D$306,DCF!D$6))} -> 0 | E13: {=TRANSPOSE(SUMIFS(Графики!$H$7:$H$306,Графики!$D$7:$D$306,DCF!E$6))} -> 0 | F13: {=TRANSPOSE(SUMIFS(Графики!$H$7:$H$306,Графики!$D$7:$D$306,DCF!F$6))} -> 0 | G13: {=TRANSPOSE(SUMIFS(Графики!$H$7:$H$306,Графики!$D$7:$D$306,DCF!G$6))} -> 0 | H13: {=TRANSPOSE(SUMIFS(Графики!$H$7:$H$306,Графики!$D$7:$D$306,DCF!H$6))} -> 0 | I13: {=TRANSPOSE(SUMIFS(Графики!$H$7:$H$306,Графики!$D$7:$D$306,DCF!I$6))} -> 0 | J13: {=TRANSPOSE(SUMIFS(Графики!$H$7:$H$306,Графики!$D$7:$D$306,DCF!J$6))} -> 0 | K13: {=TRANSPOSE(SUMIFS(Графики!$H$7:$H$306,Графики!$D$7:$D$306,DCF!K$6))} -> 0 | ... KQ13: {=TRANSPOSE(SUMIFS(Графики!$H$7:$H$306,Графики!$D$7:$D$306,DCF!KQ$6))} -> 0
B14: Вознаграждение по займам | C14: =SUM(D14:KQ14) -> 112218750 | D14: {=TRANSPOSE(SUMIFS(Графики!$J$7:$J$306,Графики!$D$7:$D$306,DCF!D$6))} -> 11812500 | E14: {=TRANSPOSE(SUMIFS(Графики!$J$7:$J$306,Графики!$D$7:$D$306,DCF!E$6))} -> 11156250 | F14: {=TRANSPOSE(SUMIFS(Графики!$J$7:$J$306,Графики!$D$7:$D$306,DCF!F$6))} -> 10500000 | G14: {=TRANSPOSE(SUMIFS(Графики!$J$7:$J$306,Графики!$D$7:$D$306,DCF!G$6))} -> 9843750 | H14: {=TRANSPOSE(SUMIFS(Графики!$J$7:$J$306,Графики!$D$7:$D$306,DCF!H$6))} -> 9187500 | I14: {=TRANSPOSE(SUMIFS(Графики!$J$7:$J$306,Графики!$D$7:$D$306,DCF!I$6))} -> 8531250 | J14: {=TRANSPOSE(SUMIFS(Графики!$J$7:$J$306,Графики!$D$7:$D$306,DCF!J$6))} -> 7875000 | K14: {=TRANSPOSE(SUMIFS(Графики!$J$7:$J$306,Графики!$D$7:$D$306,DCF!K$6))} -> 7218750 | ... KQ14: {=TRANSPOSE(SUMIFS(Графики!$J$7:$J$306,Графики!$D$7:$D$306,DCF!KQ$6))} -> 0
B15: Свободный денежный поток по опер. деятельности | C15: =SUM(D15:KQ15) -> 3.4384751e+09 | D15: =D11-SUM(D12:D14) -> 76253938 | E15: =E11-SUM(E12:E14) -> 76910188 | F15: =F11-SUM(F12:F14) -> 77566438 | G15: =G11-SUM(G12:G14) -> 19889547 | H15: =H11-SUM(H12:H14) -> -3126476 | I15: =I11-SUM(I12:I14) -> 31915347 | J15: =J11-SUM(J12:J14) -> 32571597 | K15: =K11-SUM(K12:K14) -> -59490867 | ... KQ15: =KQ11-SUM(KQ12:KQ14) -> 0
B16: Приобретение ЗУ | C16: =SUM(D16:KQ16) -> 675000000 | D16: {=TRANSPOSE(SUMIFS(Графики!$E$7:$E$306,Графики!$D$7:$D$306,DCF!D$6))} -> 0 | E16: {=TRANSPOSE(SUMIFS(Графики!$E$7:$E$306,Графики!$D$7:$D$306,DCF!E$6))} -> 0 | F16: {=TRANSPOSE(SUMIFS(Графики!$E$7:$E$306,Графики!$D$7:$D$306,DCF!F$6))} -> 0 | G16: {=TRANSPOSE(SUMIFS(Графики!$E$7:$E$306,Графики!$D$7:$D$306,DCF!G$6))} -> 0 | H16: {=TRANSPOSE(SUMIFS(Графики!$E$7:$E$306,Графики!$D$7:$D$306,DCF!H$6))} -> 0 | I16: {=TRANSPOSE(SUMIFS(Графики!$E$7:$E$306,Графики!$D$7:$D$306,DCF!I$6))} -> 0 | J16: {=TRANSPOSE(SUMIFS(Графики!$E$7:$E$306,Графики!$D$7:$D$306,DCF!J$6))} -> 0 | K16: {=TRANSPOSE(SUMIFS(Графики!$E$7:$E$306,Графики!$D$7:$D$306,DCF!K$6))} -> 0 | ... KQ16: {=TRANSPOSE(SUMIFS(Графики!$E$7:$E$306,Графики!$D$7:$D$306,DCF!KQ$6))} -> 0
B17: Соц нагрузка | C17: =SUM(D17:KQ17) -> 0 | D17: {=TRANSPOSE(SUMIFS(Графики!$G$7:$G$306,Графики!$D$7:$D$306,DCF!D$6))} -> 0 | E17: {=TRANSPOSE(SUMIFS(Графики!$G$7:$G$306,Графики!$D$7:$D$306,DCF!E$6))} -> 0 | F17: {=TRANSPOSE(SUMIFS(Графики!$G$7:$G$306,Графики!$D$7:$D$306,DCF!F$6))} -> 0 | G17: {=TRANSPOSE(SUMIFS(Графики!$G$7:$G$306,Графики!$D$7:$D$306,DCF!G$6))} -> 0 | H17: {=TRANSPOSE(SUMIFS(Графики!$G$7:$G$306,Графики!$D$7:$D$306,DCF!H$6))} -> 0 | I17: {=TRANSPOSE(SUMIFS(Графики!$G$7:$G$306,Графики!$D$7:$D$306,DCF!I$6))} -> 0 | J17: {=TRANSPOSE(SUMIFS(Графики!$G$7:$G$306,Графики!$D$7:$D$306,DCF!J$6))} -> 0 | K17: {=TRANSPOSE(SUMIFS(Графики!$G$7:$G$306,Графики!$D$7:$D$306,DCF!K$6))} -> 0 | ... JY17: {=TRANSPOSE(SUMIFS(Графики!$G$7:$G$306,Графики!$D$7:$D$306,DCF!JY$6))} -> 0 | JZ17: {=TRANSPOSE(SUMIFS(Графики!$E$7:$E$306,Графики!$D$7:$D$306,DCF!JZ$6))} -> 0 | KA17: {=TRANSPOSE(SUMIFS(Графики!$G$7:$G$306,Графики!$D$7:$D$306,DCF!KA$6))} -> 0 | KB17: {=TRANSPOSE(SUMIFS(Графики!$G$7:$G$306,Графики!$D$7:$D$306,DCF!KB$6))} -> 0 | KC17: {=TRANSPOSE(SUMIFS(Графики!$G$7:$G$306,Графики!$D$7:$D$306,DCF!KC$6))} -> 0 | KD17: {=TRANSPOSE(SUMIFS(Графики!$G$7:$G$306,Графики!$D$7:$D$306,DCF!KD$6))} -> 0 | KE17: {=TRANSPOSE(SUMIFS(Графики!$G$7:$G$306,Графики!$D$7:$D$306,DCF!KE$6))} -> 0 | KF17: {=TRANSPOSE(SUMIFS(Графики!$G$7:$G$306,Графики!$D$7:$D$306,DCF!KF$6))} -> 0 | KG17: {=TRANSPOSE(SUMIFS(Графики!$G$7:$G$306,Графики!$D$7:$D$306,DCF!KG$6))} -> 0 | KH17: {=TRANSPOSE(SUMIFS(Графики!$G$7:$G$306,Графики!$D$7:$D$306,DCF!KH$6))} -> 0 | ... KQ17: {=TRANSPOSE(SUMIFS(Графики!$G$7:$G$306,Графики!$D$7:$D$306,DCF!KQ$6))} -> 0
B18: Проектирование | C18: =SUM(D18:KQ18) -> 197152741 | D18: {=TRANSPOSE(SUMIFS(Графики!$F$7:$F$306,Графики!$D$7:$D$306,DCF!D$6))} -> 15772219 | E18: {=TRANSPOSE(SUMIFS(Графики!$F$7:$F$306,Графики!$D$7:$D$306,DCF!E$6))} -> 15772219 | F18: {=TRANSPOSE(SUMIFS(Графики!$F$7:$F$306,Графики!$D$7:$D$306,DCF!F$6))} -> 15772219 | G18: {=TRANSPOSE(SUMIFS(Графики!$F$7:$F$306,Графики!$D$7:$D$306,DCF!G$6))} -> 15772219 | H18: {=TRANSPOSE(SUMIFS(Графики!$F$7:$F$306,Графики!$D$7:$D$306,DCF!H$6))} -> 15772219 | I18: {=TRANSPOSE(SUMIFS(Графики!$F$7:$F$306,Графики!$D$7:$D$306,DCF!I$6))} -> 15772219 | J18: {=TRANSPOSE(SUMIFS(Графики!$F$7:$F$306,Графики!$D$7:$D$306,DCF!J$6))} -> 15772219 | K18: {=TRANSPOSE(SUMIFS(Графики!$F$7:$F$306,Графики!$D$7:$D$306,DCF!K$6))} -> 15772219 | ... KQ18: {=TRANSPOSE(SUMIFS(Графики!$F$7:$F$306,Графики!$D$7:$D$306,DCF!KQ$6))} -> 0
B19: Свободный денежный поток от инвестиционной деятельности | C19: =SUM(D19:KQ19) -> -872152741 | D19: =-SUM(D16:D18) -> -15772219 | E19: =-SUM(E16:E18) -> -15772219 | F19: =-SUM(F16:F18) -> -15772219 | G19: =-SUM(G16:G18) -> -15772219 | H19: =-SUM(H16:H18) -> -15772219 | I19: =-SUM(I16:I18) -> -15772219 | J19: =-SUM(J16:J18) -> -15772219 | K19: =-SUM(K16:K18) -> -15772219 | ... KQ19: =-SUM(KQ16:KQ18) -> 0
B21: FCFF | C21: =SUM(D21:KQ21) -> 2.5663224e+09 | D21: =D15+D19 -> 60481718 | E21: =E15+E19 -> 61137968 | F21: =F15+F19 -> 61794218 | G21: =G15+G19 -> 4117327.7 | H21: =H15+H19 -> -18898695 | I21: =I15+I19 -> 16143128 | J21: =J15+J19 -> 16799378 | K21: =K15+K19 -> -75263086 | ... KQ21: =KQ15+KQ19 -> 0
B22: Поступление по фин.деят (ОД) | C22: =SUM(D22:KQ22) -> 675000000 | H22: ='Dashboard все'!F24 -> 675000000
B23: Equity | C23: =SUM(D23:KQ23) -> 0
B24: Партнеры/рассрочка | C24: =SUM(D24:KQ24) -> 0
B25: Оттоки по фин.деят (ОД) | C25: =SUM(D25:KQ25) -> 675000000 | D25: {=TRANSPOSE(SUMIFS(Графики!$K$7:$K$306,Графики!$D$7:$D$306,DCF!D$6))} -> 37500000 | E25: {=TRANSPOSE(SUMIFS(Графики!$K$7:$K$306,Графики!$D$7:$D$306,DCF!E$6))} -> 37500000 | F25: {=TRANSPOSE(SUMIFS(Графики!$K$7:$K$306,Графики!$D$7:$D$306,DCF!F$6))} -> 37500000 | G25: {=TRANSPOSE(SUMIFS(Графики!$K$7:$K$306,Графики!$D$7:$D$306,DCF!G$6))} -> 37500000 | H25: {=TRANSPOSE(SUMIFS(Графики!$K$7:$K$306,Графики!$D$7:$D$306,DCF!H$6))} -> 37500000 | I25: {=TRANSPOSE(SUMIFS(Графики!$K$7:$K$306,Графики!$D$7:$D$306,DCF!I$6))} -> 37500000 | J25: {=TRANSPOSE(SUMIFS(Графики!$K$7:$K$306,Графики!$D$7:$D$306,DCF!J$6))} -> 37500000 | K25: {=TRANSPOSE(SUMIFS(Графики!$K$7:$K$306,Графики!$D$7:$D$306,DCF!K$6))} -> 37500000 | ... KQ25: {=TRANSPOSE(SUMIFS(Графики!$K$7:$K$306,Графики!$D$7:$D$306,DCF!KQ$6))} -> 0
B26: Возврат Equity | C26: =SUM(D26:KQ26) -> 0
B27: Возврат партнеры/рассрочка | C27: =SUM(D27:KQ27) -> 0
B28: Выплата ДВД | C28: =SUM(D28:KQ28) -> 0
B29: Свободный денежный поток от ФИН деятельности | C29: =SUM(D29:KQ29) -> 0 | D29: =D22+D23+D24-D25-D26-D28-D27 -> -37500000 | E29: =E22+E23+E24-E25-E26-E28-E27 -> -37500000 | F29: =F22+F23+F24-F25-F26-F28-F27 -> -37500000 | G29: =G22+G23+G24-G25-G26-G28-G27 -> -37500000 | H29: =H22+H23+H24-H25-H26-H28-H27 -> 637500000 | I29: =I22+I23+I24-I25-I26-I28-I27 -> -37500000 | J29: =J22+J23+J24-J25-J26-J28-J27 -> -37500000 | K29: =K22+K23+K24-K25-K26-K28-K27 -> -37500000 | ... KQ29: =KQ22+KQ23+KQ24-KQ25-KQ26-KQ28-KQ27 -> 0
B31: FCFE | C31: =SUM(D31:KQ31) -> 2.5663224e+09 | D31: =D21+D29 -> 22981718 | E31: =E21+E29 -> 23637968 | F31: =F21+F29 -> 24294218 | G31: =G21+G29 -> -33382672 | H31: =H21+H29 -> 6.186013e+08 | I31: =I21+I29 -> -21356872 | J31: =J21+J29 -> -20700622 | K31: =K21+K29 -> -1.1276309e+08 | ... KQ31: =KQ21+KQ29 -> 0
B34: Накопительный денежный поток | C34: KZT | D34: =D31 -> 22981718 | E34: =D34+E31 -> 46619687 | F34: =E34+F31 -> 70913905 | G34: =F34+G31 -> 37531233 | H34: =G34+H31 -> 6.5613254e+08 | I34: =H34+I31 -> 6.3477566e+08 | J34: =I34+J31 -> 6.1407504e+08 | K34: =J34+K31 -> 5.0131196e+08 | L34: =K34+L31 -> 4.3430399e+08 | ... KQ34: =KP34+KQ31 -> 2.5663224e+09
B35: Дисконтированный поток | C35: KZT | D35: =D21/(1+$C$47)^D4 -> 59441492 | E35: =E21/(1+$C$47)^E4 -> 59053027 | F35: =F21/(1+$C$47)^F4 -> 58660342 | G35: =G21/(1+$C$47)^G4 -> 3841295.9 | H35: =H21/(1+$C$47)^H4 -> -17328451 | I35: =I21/(1+$C$47)^I4 -> 14547259 | J35: =J21/(1+$C$47)^J4 -> 14878264 | K35: =K21/(1+$C$47)^K4 -> -65509861 | ... KQ35: =KQ21/(1+$C$47)^KQ4 -> 0
B36: Накопительный денежный поток | C36: KZT | D36: =D35 -> 59441492 | E36: =E35 -> 59053027 | F36: =F35 -> 58660342 | G36: =G35 -> 3841295.9 | H36: =H35 -> -17328451 | I36: =I35 -> 14547259 | J36: =J35 -> 14878264 | K36: =K35 -> -65509861 | ... KQ36: =KQ35 -> 0
B37: Индекс окупаемости, мес | C37: {=MATCH(TRUE,D34:JX34>=C23,0)} -> 1 | D37: =IF(D36<0,1,0) -> 0 | E37: =IF(E36<0,1,0) -> 0 | F37: =IF(F36<0,1,0) -> 0 | G37: =IF(G36<0,1,0) -> 0 | H37: =IF(H36<0,1,0) -> 1 | I37: =IF(I36<0,1,0) -> 0 | J37: =IF(J36<0,1,0) -> 0 | K37: =IF(K36<0,1,0) -> 1 | ... KQ37: =IF(KQ36<0,1,0) -> 0
B40: Equity discount rate | C40: =18%/12 -> 0.015
B41: IRR FCFF | C41: =IRR(D51:D52) -> 15.142248
B42: NPV FCFF | C42: =NPV(C40,E21:FA21)+D21 -> 1.8777444e+09
B44: ROE | C44: =IFERROR(C21/C23, 0) -> 0
B45: ROI | C45: =IFERROR(C21/SUM(C22:C24),0) -> 3.8019591
B46: DPP | C46: =C37 -> 1
B47: WACC месячный | C47: =21%/12 -> 0.0175
B48: ROI | C48: =IFERROR(C21/SUM(C22:C24),0) -> 3.8019591
C51: 2026 | D51: =SUM(D21:P21) -> -1.6948094e+08
...

Sheet Цена
A1: № | B1: Площадь | C1: Офис | D1: 1057000 | E1: 0.012 | F1: Сумма | H1: Коммерция | J1: 1287500
A2: 603 | B2: 143.9 | C2: 11 | D2: =D1+D1*$E$1 -> 1069684 | E2: 0.0115 | F2: =B2*D2 -> 1.5392753e+08 | H2: C101 | I2: 138.79 | J2: =J1+J1*K2 -> 1301662.5 | K2: 0.011 | L2: =I2*J2 -> 1.8065774e+08
A3: 703 | B3: 143.9 | C3: 15 | D3: =D2+D2*$E$1 -> 1082520.2 | E3: 0.011 | F3: =B3*D3 -> 1.5577466e+08 | H3: C102 | I3: 268.95 | J3: =J1+J1*K3 -> 1301018.8 | K3: 0.0105 | L3: =I3*J3 -> 3.4990899e+08
A4: 803 | B4: 143.9 | C4: 19 | D4: =D3+D3*$E$1 -> 1095510.5 | F4: =B4*D4 -> 1.5764395e+08 | J4: =AVERAGE(J2:J3) -> 1301340.6 | L4: =SUM(L2:L3) -> 5.3056673e+08
A5: 602 | B5: 143.96 | C5: 10 | D5: =D4+D4*$E$1 -> 1108656.6 | F5: =B5*D5 -> 1.596022e+08
A6: 702 | B6: 143.96 | C6: 14 | D6: =D5+D5*$E$1 -> 1121960.5 | F6: =B6*D6 -> 1.6151743e+08
A7: 802 | B7: 143.96 | C7: 18 | D7: =D6+D6*$E$1 -> 1135424 | F7: =B7*D7 -> 1.6345564e+08
A8: 202 | B8: 206.76 | C8: 2 | D8: =D1+$D$1*$E$2 -> 1069155.5 | F8: =B8*D8 -> 2.2105859e+08
A9: 601 | B9: 218.81 | C9: 9 | D9: =D8+D8*$E$2 -> 1081450.8 | F9: =B9*D9 -> 2.3663225e+08
A10: 701 | B10: 218.81 | C10: 13 | D10: =D9+D9*$E$2 -> 1093887.5 | F10: =B10*D10 -> 2.3935352e+08
A11: 801 | B11: 218.81 | C11: 17 | D11: =D10+D10*$E$2 -> 1106467.2 | F11: =B11*D11 -> 2.4210608e+08
A12: 604 | B12: 221.38 | C12: 12 | D12: =D11+D11*$E$2 -> 1119191.6 | F12: =B12*D12 -> 2.4776663e+08
A13: 704 | B13: 221.38 | C13: 16 | D13: =D12+D12*$E$2 -> 1132062.3 | F13: =B13*D13 -> 2.5061594e+08
A14: 804 | B14: 221.38 | C14: 20 | D14: =D13+D13*$E$2 -> 1145081 | F14: =B14*D14 -> 2.5349803e+08
A15: 201 | B15: 345.9 | C15: 1 | D15: =D1 -> 1057000 | F15: =B15*D15 -> 365616300
A16: 301 | B16: 363.47 | C16: 3 | D16: =D15+D15*$E$3 -> 1068627 | F16: =B16*D16 -> 3.8841386e+08
A17: 401 | B17: 363.87 | C17: 5 | D17: =D16+D16*$E$3 -> 1080381.9 | F17: =B17*D17 -> 3.9311856e+08
A18: 501 | B18: 366.11 | C18: 7 | D18: =D17+D17*$E$3 -> 1092266.1 | F18: =B18*D18 -> 3.9988954e+08
A19: 302 | B19: 366.28 | C19: 4 | D19: =D18+D18*$E$3 -> 1104281 | F19: =B19*D19 -> 4.0447605e+08
A20: 402 | B20: 366.28 | C20: 6 | D20: =D19+D19*$E$3 -> 1116428.1 | F20: =B20*D20 -> 4.0892529e+08
A21: 502 | B21: 369.09 | C21: 8 | D21: =D20+D20*$E$3 -> 1128708.8 | F21: =B21*D21 -> 4.1659514e+08
A22: 1001 | B22: 560.69 | C22: 22 | D22: =D1+D21*$E$3 -> 1069415.8 | F22: =B22*D22 -> 5.9961074e+08
A23: 901 | B23: 700.45 | C23: 21 | D23: =D1 -> 1057000 | F23: =B23*D23 -> 740375650
B24: =SUM(B2:B23) -> 6193.05 | D24: =AVERAGE(D2:D23) -> 1097052.7 | F24: =SUM(F2:F23) -> 6.7599736e+09

Sheet Sensitivity
B2: Изменение Цены реализации м2 | E2: Сред. Цена, тг | F2: =F5/F4 -> 1552427.2
B3: Изменение Себестоимости | E3: Себес-ть, млн.тг | F3: ='PnL все'!B39+'PnL все'!B73 -> 8.1469776e+09
B4: Изменение м2 | E4: Объем, м2 | F4: ='PnL все'!B7 -> 6901
E5: Выручка, млн.тг | F5: ='PnL все'!B34 -> 10713300000
E6: ЧП, млн.тг | F6: ='PnL все'!B74 -> 2.5663224e+09
B8: Анализ чувствительности
B10: Изменение ЧП | E10: Изменение стоимости проекта м2
E11: =F11*(1+E12) -> 1009370.5 | F11: =G11*(1+F12) -> 1121522.8 | G11: =F3/F4 -> 1180550.3 | H11: =G11*(1+H12) -> 1239577.8 | I11: =G11*(1+I12) -> 1298605.3
E12: =D13 -> -0.1 | F12: =D14 -> -0.05 | G12: =D15 -> 0 | H12: =D16 -> 0.05 | I12: =D17 -> 0.1
B13: Изменение Цены реализации м2 | C13: =C15*(1+D13) -> 1397184.5 | D13: -0.1 | E13: =$C13*$F$4-E$11*$F$4 -> 2.6763041e+09 | F13: =$C13*$F$4-F$11*$F$4 -> 1.9023413e+09 | G13: =$C13*$F$4-G$11*$F$4 -> 1.4949924e+09 | H13: =$C13*$F$4-H$11*$F$4 -> 1.0876435e+09 | I13: =$C13*$F$4-I$11*$F$4 -> 6.8029463e+08
C14: =C15*(1+D14) -> 1474805.8 | D14: -0.05 | E14: =$C14*$F$4-E$11*$F$4 -> 3.2119691e+09 | F14: =$C14*$F$4-F$11*$F$4 -> 2.4380063e+09 | G14: =$C14*$F$4-G$11*$F$4 -> 2.0306574e+09 | H14: =$C14*$F$4-H$11*$F$4 -> 1.6233085e+09 | I14: =$C14*$F$4-I$11*$F$4 -> 1.2159596e+09
C15: =VLOOKUP(B13,B2:F4,5,FALSE) -> 1552427.2 | D15: 0 | E15: =$C15*$F$4-E$11*$F$4 -> 3.7476341e+09 | F15: =$C15*$F$4-F$11*$F$4 -> 2.9736713e+09 | G15: =$C15*$F$4-G$11*$F$4 -> 2.5663224e+09 | H15: =$C15*$F$4-H$11*$F$4 -> 2.1589735e+09 | I15: =$C15*$F$4-I$11*$F$4 -> 1.7516246e+09
C16: =C15*(1+D16) -> 1630048.5 | D16: =-D14 -> 0.05 | E16: =$C16*$F$4-E$11*$F$4 -> 4.2832991e+09 | F16: =$C16*$F$4-F$11*$F$4 -> 3.5093363e+09 | G16: =$C16*$F$4-G$11*$F$4 -> 3.1019874e+09 | H16: =$C16*$F$4-H$11*$F$4 -> 2.6946385e+09 | I16: =$C16*$F$4-I$11*$F$4 -> 2.2872896e+09
C17: =C15*(1+D17) -> 1707669.9 | D17: =-D13 -> 0.1 | E17: =$C17*$F$4-E$11*$F$4 -> 4.8189641e+09 | F17: =$C17*$F$4-F$11*$F$4 -> 4.0450013e+09 | G17: =$C17*$F$4-G$11*$F$4 -> 3.6376524e+09 | H17: =$C17*$F$4-H$11*$F$4 -> 3.2303035e+09 | I17: =$C17*$F$4-I$11*$F$4 -> 2.8229546e+09
B19: Изменение Рентабельности | E19: Изменение стоимости проекта м2
E20: =E11 -> 1009370.5 | F20: =F11 -> 1121522.8 | G20: =G11 -> 1180550.3 | H20: =H11 -> 1239577.8 | I20: =I11 -> 1298605.3
E21: =E12 -> -0.1 | F21: =F12 -> -0.05 | G21: =G12 -> 0 | H21: =H12 -> 0.05 | I21: =I12 -> 0.1
B22: Изменение средней цены за м2 | C22: =C13 -> 1397184.5 | D22: =C22/$C$23 -> 0.94736842 | E22: =E13/$F$5 -> 0.24981137 | F22: =F13/$F$5 -> 0.17756819 | G22: =G13/$F$5 -> 0.13954546 | H22: =H13/$F$5 -> 0.10152273 | I22: =I13/$F$5 -> 0.063500008
C23: =C14 -> 1474805.8 | D23: =C23/$C$23 -> 1 | E23: =E14/$F$5 -> 0.29981137 | F23: =F14/$F$5 -> 0.22756819 | G23: =G14/$F$5 -> 0.18954546 | H23: =H14/$F$5 -> 0.15152273 | I23: =I14/$F$5 -> 0.11350001
C24: =C15 -> 1552427.2 | D24: =C24/$C$23 -> 1.0526316 | E24: =E15/$F$5 -> 0.34981137 | F24: =F15/$F$5 -> 0.27756819 | G24: =G15/$F$5 -> 0.23954546 | H24: =H15/$F$5 -> 0.20152273 | I24: =I15/$F$5 -> 0.16350001
C25: =C16 -> 1630048.5 | D25: =C25/$C$23 -> 1.1052632 | E25: =E16/$F$5 -> 0.39981137 | F25: =F16/$F$5 -> 0.32756819 | G25: =G16/$F$5 -> 0.28954546 | H25: =H16/$F$5 -> 0.25152273 | I25: =I16/$F$5 -> 0.21350001
C26: =C17 -> 1707669.9 | D26: =C26/$C$23 -> 1.1578947 | E26: =E17/$F$5 -> 0.44981137 | F26: =F17/$F$5 -> 0.37756819 | G26: =G17/$F$5 -> 0.33954546 | H26: =H17/$F$5 -> 0.30152273 | I26: =I17/$F$5 -> 0.26350001

Sheet Dashboard (с перегор)
B3: Итоговые показатели
B4: Net Profit | C4: ='PnL (с перегор)'!B74 -> #REF!
B5: ROS, % | C5: ='PnL все'!B75 -> 0.23954546
B6: ROE (Отдача на капитал) | C6: =DCF!C44 -> 0
B7: WACC (Годовой) | C7: =DCF!C47*12 -> 0.21
B8: IRR (Минимальная ставка доходности) | C8: =DCF!C41*12 -> 181.70697
B9: NPV | C9: =DCF!C42 -> 1.8777444e+09
B10: PP | C10: =DCF!C37 -> 1
B11: DPP | C11: =DCF!C46 -> 1
B14: Основные вводные
B15: LAND | E15: SALES | H15: COSTS | K15: Sellable Area, sq.m | L15: =SUM(L16:L19) -> 12968.198
B16: Площадь ЗУ, га | C16: 1.1062 | E16: Цена за м2 квартиры | F16: 650000 | H16: Себестоимость за м2 | I16: 285417.25 | K16: Квартиры | L16: =11801.735625-720 -> 11081.736
B17: Курс ЗУ | C17: 470.46 | E17: Цена за м2 офиса | F17: 0 | H17: Накладные расходы | I17: 22701.345 | K17: Офисы | L17: 0
B18: Стоимость за сотку, USD | C18: 25000 | E18: Цена за м2 кладовки | F18: 150000 | H18: Расходы на реализацию | I18: 0.0455 | K18: Кладовые | L18: 841.46211
B19: Стоимость участка итого, KZT | C19: =C16*100*C18*C17 -> 1301057130 | E19: Цена за 1 м/м | F19: 6000000 | H19: Расходы офиса | I19: 0.024 | K19: Паркинг | L19: =L26*13.75 -> 1045
H20: ПИРы | I20: 7902.8232
B22: CONSTRUCTION | E22: CASH FLOW | H22: TAXES | K22: Sellable Units, pcs | L22: =SUM(L23:L26) -> 469
B23: Этажность | C23: 9 | E23: Собственный капитал | H23: НДС | I23: ='PnL все'!B70 -> 6.8771146e+08 | K23: Квартиры | L23: 240
B24: Застраиваемая площадь | E24: Кредит | F24: 200000000 | H24: КПН | I24: ='PnL все'!B73 -> 6.415806e+08 | K24: Офисы | L24: 0
B25: Продаваемая площадь | C25: ='PnL все'!B7 -> 6901 | E25: Срок займа, мес | F25: 18 | K25: Кладовые | L25: 153
B26: Прод площ 1 очереди | C26: =C25 -> 6901 | E26: Дивиденды | F26: ='PnL все'!B74 -> 2.5663224e+09 | K26: Паркинг | L26: 76
E27: Дата займа | F27: 46327
B28: ЖЦП, мес | C28: 16 | E28: Ставка, % | F28: 21
B29: Дата старта | C29: 46174 | E29: Льготный период, мес | F29: 6
B34: Собственный капитал | C34: 0
B35: Ставка займа (годовая) | C35: 0.21
B36: Стоимость акционерских денег | C36: 0.25

Sheet PnL (с перегор)
A2: Показатель | B2: KZT | C2: USD
A3: Цена за сотку (Общая), USD | B3: =B48/B5/100/B4 -> 90000
A4: Курс $ | B4: ='Dashboard все'!C17 -> 500
A5: Земельный участок га | B5: ='Dashboard все'!C16 -> 0.15
A6: Этажность | B6: ='Dashboard все'!C23 -> 10
A7: Реализуемая площадь, м2 | B7: =SUM(B8:B11) -> 17982.736 | C7: =B7 -> 17982.736
A8: Квартиры (себес м2 * площадь) | B8: ='Dashboard (с перегор)'!L16 -> 11081.736 | C8: =B8 -> 11081.736
A9: Коммерческие помещения | B9: ='Dashboard все'!L17 -> 6232 | C9: =B9 -> 6232
A10: Кладовые помещения | B10: ='Dashboard все'!L18 -> 253 | C10: =B10 -> 253
A11: Паркинги | B11: ='Dashboard все'!L19 -> 416 | C11: =B11 -> 416
A12: Реализуемое количество, шт | B12: =SUM(B13:B16) -> 50 | C12: =B12 -> 50
A13: Квартиры (себес м2 * площадь) | B13: ='Dashboard все'!L23 -> 0 | C13: =B13 -> 0
A14: Коммерческие помещения | B14: ='Dashboard все'!L24 -> 22 | C14: =B14 -> 22
A15: Кладовые помещения | B15: ='Dashboard все'!L25 -> 2 | C15: =B15 -> 2
A16: Паркинги | B16: ='Dashboard все'!L26 -> 26 | C16: =B16 -> 26
A17: Средние цены реализации: | B17: =B34/B7 -> 411343.32 | C17: =C34/C7 -> 822.68664
A18: Квартиры (себес м2 * площадь) | B18: ='Dashboard (с перегор)'!F16 -> 650000 | C18: =B18/$B$4 -> 1300
A19: Коммерческие помещения | B19: ='Dashboard (с перегор)'!F17 -> 0 | C19: =B19/$B$4 -> 0
A20: Кладовые помещения | B20: ='Dashboard (с перегор)'!F18 -> 150000 | C20: =B20/$B$4 -> 300
A21: Паркинги | B21: ='Dashboard (с перегор)'!F19 -> 6000000 | C21: =B21/$B$4 -> 12000
A22: Cебестоимость СМР за м2: | B22: =(B41+B42+B43+B44)/(B8+B9+B10+B11) -> 692590.51 | C22: =B22/$B$4 -> 1385.181
A23: Квартиры (себес м2 * площадь) | B23: ='Dashboard все'!I16 -> 665927.82 | C23: =B23/$B$4 -> 1331.8556
A24: Коммерческие помещения | B24: 0 | C24: =B24/$B$4 -> 0
A25: Кладовые помещения | B25: 0 | C25: =B25/$B$4 -> 0
A26: Паркинги | C26: =B26/$B$4 -> 0
A27: Средняя себестоимость (СМР+ПСД+опер.+накл.) | B27: =SUM(B28:B33) -> 862752.55 | C27: =B27/$B$4 -> 1725.5051
A28: Строительно-монтажные работы | B28: =B40/(B8+B9+B10+B11) -> 692590.51 | C28: =B28/$B$4 -> 1385.181
A29: Земельный участок | B29: =B48/B7 -> 37536.002 | C29: =B29/$B$4 -> 75.072004
A30: Расходы заказчика | B30: =B50/B7 -> 29712.567 | C30: =B30/$B$4 -> 59.425133
A31: Накладные расходы | B31: =B52/B7 -> 102913.48 | C31: =B31/$B$4 -> 205.82696
A32: Социальная нагрузка | B32: 0 | C32: =B32/$B$4 -> 0
A33: % по кредиту | B33: 0 | C33: =B33/$B$4 -> 0
A34: Выручка итого в т.ч. | B34: =SUM(B35:B38) -> 7.3970782e+09 | C34: =B34/B4 -> 14794156
A35: Квартиры (себес м2 * площадь) | B35: =(B8*B18) -> 7.2031282e+09 | C35: =B35/$B$4 -> 14406256
A36: Коммерческие помещения | B36: =(B9*B19) -> 0 | C36: =B36/$B$4 -> 0
A37: Кладовые помещения | B37: =(B10*B20) -> 37950000 | C37: =B37/$B$4 -> 75900
A38: Паркинги | B38: =(B16*B21) -> 156000000 | C38: =B38/$B$4 -> 312000
A39: Расходы итого: | B39: =B40+B48+B50+B52+B62+B66+B68+B70 -> #REF! | C39: =B39/$B$4 -> #REF!
A40: СМР в т.ч.: | B40: =SUM(B41:B47) -> 1.2454672e+10 | C40: =B40/$B$4 -> 24909344
A41: СМР(себес м2 * площадь) | B41: =(B7+720)*'Dashboard все'!I16 -> 1.2454672e+10
...

Sheet Credit
A1: РАВНЫМИ ДОЛЯМИ | H1: не удалять
A2: Сумма | D2: ='Dashboard все'!F24 -> 675000000 | H2: АННУИТЕТ | I2: 46027
A3: Срок (мес) | D3: ='Dashboard (с перегор)'!F25 -> 18 | H3: РАВНЫМИ ДОЛЯМИ | I3: 47092
A4: % годовые | D4: ='Dashboard все'!F28 -> 21 | H4: ло | I4: =I3-I2 -> 1065
A5: Льготный период | D5: ='Dashboard все'!F29 -> 0 | H5: TRUE | I5: =I4/30 -> 35.5
A6: Дата первого взноса | D6: ='Dashboard все'!F27 -> 46204
A7: =IF(A1="АННУИТЕТ","Ежемесячный платеж","Ежемесячный платеж от") -> Ежемесячный платеж от | D7: =IF(H5=TRUE,IF($A$1="АННУИТЕТ",-PMT($D$4/(12*100),$D$3-$D$5,$D$2),$D$2/($D$3-$D$5)+$D$2*$D$4/(12*100)),IF($A$1="АННУИТЕТ",-PMT($D$4/(12*100),$D$3,$D$2),$D$2/($D$3)+$D$2*$D$4/(12*100))) -> 49312500
A8: % к выплате | D8: =SUM(D12:D251) -> 112218750
A9: Сумма к выплате | D9: =SUM(E12:E251) -> 787218750
A10: Дата взноса | B10: Взнос | C10: Выплаты по ОД | D10: Выплата процентов | E10: Сумма к выплате | F10: Сальдо капитала
F11: =D2 -> 675000000
A12: =IF($D$3>=B12,DATE(YEAR($D$6),MONTH($D$6)+B12-1,DAY($D$6)),0) -> 46204 | B12: 1 | C12: =IF(F11<0.01,0,IF($H$5=TRUE,IF(B12<=$D$5,0,IF($A$1="АННУИТЕТ",$D$7-D12,$D$2/($D$3-$D$5))),IF($A$1="АННУИТЕТ",$D$7-D12,$D$2/$D$3))) -> 37500000 | D12: =F11*($D$4/12)/100 -> 11812500 | E12: =IF($A$1="АННУИТЕТ",IF(F11>0,C12+D12,0),C12+D12) -> 49312500 | F12: =F11-C12 -> 637500000
A13: =IF($D$3>=B13,DATE(YEAR($D$6),MONTH($D$6)+B13-1,DAY($D$6)),0) -> 46235 | B13: 2 | C13: =IF(F12<0.01,0,IF($H$5=TRUE,IF(B13<=$D$5,0,IF($A$1="АННУИТЕТ",$D$7-D13,$D$2/($D$3-$D$5))),IF($A$1="АННУИТЕТ",$D$7-D13,$D$2/$D$3))) -> 37500000 | D13: =F12*($D$4/12)/100 -> 11156250 | E13: =IF($A$1="АННУИТЕТ",IF(F12>0,C13+D13,0),C13+D13) -> 48656250 | F13: =F12-C13 -> 600000000
A14: =IF($D$3>=B14,DATE(YEAR($D$6),MONTH($D$6)+B14-1,DAY($D$6)),0) -> 46266 | B14: 3 | C14: =IF(F13<0.01,0,IF($H$5=TRUE,IF(B14<=$D$5,0,IF($A$1="АННУИТЕТ",$D$7-D14,$D$2/($D$3-$D$5))),IF($A$1="АННУИТЕТ",$D$7-D14,$D$2/$D$3))) -> 37500000 | D14: =F13*($D$4/12)/100 -> 10500000 | E14: =IF($A$1="АННУИТЕТ",IF(F13>0,C14+D14,0),C14+D14) -> 48000000 | F14: =F13-C14 -> 562500000
A15: =IF($D$3>=B15,DATE(YEAR($D$6),MONTH($D$6)+B15-1,DAY($D$6)),0) -> 46296 | B15: 4 | C15: =IF(F14<0.01,0,IF($H$5=TRUE,IF(B15<=$D$5,0,IF($A$1="АННУИТЕТ",$D$7-D15,$D$2/($D$3-$D$5))),IF($A$1="АННУИТЕТ",$D$7-D15,$D$2/$D$3))) -> 37500000 | D15: =F14*($D$4/12)/100 -> 9843750 | E15: =IF($A$1="АННУИТЕТ",IF(F14>0,C15+D15,0),C15+D15) -> 47343750 | F15: =F14-C15 -> 525000000
A16: =IF($D$3>=B16,DATE(YEAR($D$6),MONTH($D$6)+B16-1,DAY($D$6)),0) -> 46327 | B16: 5 | C16: =IF(F15<0.01,0,IF($H$5=TRUE,IF(B16<=$D$5,0,IF($A$1="АННУИТЕТ",$D$7-D16,$D$2/($D$3-$D$5))),IF($A$1="АННУИТЕТ",$D$7-D16,$D$2/$D$3))) -> 37500000 | D16: =F15*($D$4/12)/100 -> 9187500 | E16: =IF($A$1="АННУИТЕТ",IF(F15>0,C16+D16,0),C16+D16) -> 46687500 | F16: =F15-C16 -> 487500000
A17: =IF($D$3>=B17,DATE(YEAR($D$6),MONTH($D$6)+B17-1,DAY($D$6)),0) -> 46357 | B17: 6 | C17: =IF(F16<0.01,0,IF($H$5=TRUE,IF(B17<=$D$5,0,IF($A$1="АННУИТЕТ",$D$7-D17,$D$2/($D$3-$D$5))),IF($A$1="АННУИТЕТ",$D$7-D17,$D$2/$D$3))) -> 37500000 | D17: =F16*($D$4/12)/100 -> 8531250 | E17: =IF($A$1="АННУИТЕТ",IF(F16>0,C17+D17,0),C17+D17) -> 46031250 | F17: =F16-C17 -> 450000000
A18: =IF($D$3>=B18,DATE(YEAR($D$6),MONTH($D$6)+B18-1,DAY($D$6)),0) -> 46388 | B18: 7 | C18: =IF(F17<0.01,0,IF($H$5=TRUE,IF(B18<=$D$5,0,IF($A$1="АННУИТЕТ",$D$7-D18,$D$2/($D$3-$D$5))),IF($A$1="АННУИТЕТ",$D$7-D18,$D$2/$D$3))) -> 37500000 | D18: =F17*($D$4/12)/100 -> 7875000 | E18: =IF($A$1="АННУИТЕТ",IF(F17>0,C18+D18,0),C18+D18) -> 45375000 | F18: =F17-C18 -> 412500000
A19: =IF($D$3>=B19,DATE(YEAR($D$6),MONTH($D$6)+B19-1,DAY($D$6)),0) -> 46419 | B19: 8 | C19: =IF(F18<0.01,0,IF($H$5=TRUE,IF(B19<=$D$5,0,IF($A$1="АННУИТЕТ",$D$7-D19,$D$2/($D$3-$D$5))),IF($A$1="АННУИТЕТ",$D$7-D19,$D$2/$D$3))) -> 37500000 | D19: =F18*($D$4/12)/100 -> 7218750 | E19: =IF($A$1="АННУИТЕТ",IF(F18>0,C19+D19,0),C19+D19) -> 44718750 | F19: =F18-C19 -> 375000000
A20: =IF($D$3>=B20,DATE(YEAR($D$6),MONTH($D$6)+B20-1,DAY($D$6)),0) -> 46447 | B20: 9 | C20: =IF(F19<0.01,0,IF($H$5=TRUE,IF(B20<=$D$5,0,IF($A$1="АННУИТЕТ",$D$7-D20,$D$2/($D$3-$D$5))),IF($A$1="АННУИТЕТ",$D$7-D20,$D$2/$D$3))) -> 37500000 | D20: =F19*($D$4/12)/100 -> 6562500 | E20: =IF($A$1="АННУИТЕТ",IF(F19>0,C20+D20,0),C20+D20) -> 44062500 | F20: =F19-C20 -> 337500000
A21: =IF($D$3>=B21,DATE(YEAR($D$6),MONTH($D$6)+B21-1,DAY($D$6)),0) -> 46478 | B21: 10 | C21: =IF(F20<0.01,0,IF($H$5=TRUE,IF(B21<=$D$5,0,IF($A$1="АННУИТЕТ",$D$7-D21,$D$2/($D$3-$D$5))),IF($A$1="АННУИТЕТ",$D$7-D21,$D$2/$D$3))) -> 37500000 | D21: =F20*($D$4/12)/100 -> 5906250 | E21: =IF($A$1="АННУИТЕТ",IF(F20>0,C21+D21,0),C21+D21) -> 43406250 | F21: =F20-C21 -> 300000000
A22: =IF($D$3>=B22,DATE(YEAR($D$6),MONTH($D$6)+B22-1,DAY($D$6)),0) -> 46508 | B22: 11 | C22: =IF(F21<0.01,0,IF($H$5=TRUE,IF(B22<=$D$5,0,IF($A$1="АННУИТЕТ",$D$7-D22,$D$2/($D$3-$D$5))),IF($A$1="АННУИТЕТ",$D$7-D22,$D$2/$D$3))) -> 37500000 | D22: =F21*($D$4/12)/100 -> 5250000 | E22: =IF($A$1="АННУИТЕТ",IF(F21>0,C22+D22,0),C22+D22) -> 42750000 | F22: =F21-C22 -> 262500000
A23: =IF($D$3>=B23,DATE(YEAR($D$6),MONTH($D$6)+B23-1,DAY($D$6)),0) -> 46539 | B23: 12 | C23: =IF(F22<0.01,0,IF($H$5=TRUE,IF(B23<=$D$5,0,IF($A$1="АННУИТЕТ",$D$7-D23,$D$2/($D$3-$D$5))),IF($A$1="АННУИТЕТ",$D$7-D23,$D$2/$D$3))) -> 37500000 | D23: =F22*($D$4/12)/100 -> 4593750 | E23: =IF($A$1="АННУИТЕТ",IF(F22>0,C23+D23,0),C23+D23) -> 42093750 | F23: =F22-C23 -> 225000000
... A371: =IF($D$3>=B371,DATE(YEAR($D$6),MONTH($D$6)+B371-1,DAY($D$6)),0) -> 0 | B371: 360 | C371: =IF(F370<0.01,0,IF($H$5=TRUE,IF(B371<=$D$5,0,IF($A$1="АННУИТЕТ",$D$7-D371,$D$2/($D$3-$D$5))),IF($A$1="АННУИТЕТ",$D$7-D371,$D$2/$D$3))) -> 0 | D371: =F370*($D$4/12)/100 -> 0 | E371: =IF($A$1="АННУИТЕТ",IF(F370>0,C371+D371,0),C371+D371) -> 0 | F371: =F370-C371 -> 0

Sheet Графики
H1: =H3-H2 -> 0
F2: =SUBTOTAL(9,F7:F306) -> 197152741 | G2: =SUBTOTAL(9,G7:G306) -> 0 | H2: =SUBTOTAL(9,H7:H306) -> 6.415806e+08 | I2: =SUBTOTAL(9,I7:I306) -> 6.8771146e+08 | J2: =SUBTOTAL(9,J7:J306) -> 112218750 | K2: =SUBTOTAL(9,K7:K306) -> 675000000
E3: ='PnL все'!B48 -> 675000000 | F3: ='PnL все'!B50 -> 197152741 | G3: ='PnL все'!B62 -> 0 | H3: ='PnL все'!B73 -> 6.415806e+08 | I3: ='PnL все'!B70 -> 6.8771146e+08 | J3: ='PnL все'!B66 -> 112218750 | K3: =Credit!D2 -> 675000000
E6: Приобретение ЗУ | F6: Проектирование | G6: Соц нагрузка | H6: КПН | I6: НДС к уплате | J6: Вознаграждение по займам | K6: Оттоки по фин.деят (ОД)
B7: 1 | C7: =MONTH(D7) -> 7 | D7: =DCF!D6 -> 46204 | F7: =$F$3*8% -> 15772219 | J7: =SUMIF(Credit!$A$12:$A$371,Графики!D7,Credit!$D$12:$D$371) -> 11812500 | K7: =SUMIF(Credit!$A$12:$A$371,Графики!D7,Credit!$C$12:$C$371) -> 37500000
B8: =B7+1 -> 2 | C8: =MONTH(D8) -> 8 | D8: =EDATE(D7,1) -> 46235 | F8: =$F$3*8% -> 15772219 | J8: =SUMIF(Credit!$A$12:$A$371,Графики!D8,Credit!$D$12:$D$371) -> 11156250 | K8: =SUMIF(Credit!$A$12:$A$371,Графики!D8,Credit!$C$12:$C$371) -> 37500000
B9: =B8+1 -> 3 | C9: =MONTH(D9) -> 9 | D9: =EDATE(D8,1) -> 46266 | F9: =$F$3*8% -> 15772219 | J9: =SUMIF(Credit!$A$12:$A$371,Графики!D9,Credit!$D$12:$D$371) -> 10500000 | K9: =SUMIF(Credit!$A$12:$A$371,Графики!D9,Credit!$C$12:$C$371) -> 37500000
B10: =B9+1 -> 4 | C10: =MONTH(D10) -> 10 | D10: =EDATE(D9,1) -> 46296 | F10: =$F$3*8% -> 15772219 | J10: =SUMIF(Credit!$A$12:$A$371,Графики!D10,Credit!$D$12:$D$371) -> 9843750 | K10: =SUMIF(Credit!$A$12:$A$371,Графики!D10,Credit!$C$12:$C$371) -> 37500000
B11: =B10+1 -> 5 | C11: =MONTH(D11) -> 11 | D11: =EDATE(D10,1) -> 46327 | F11: =$F$3*8% -> 15772219 | I11: =$I$3*5% -> 34385573 | J11: =SUMIF(Credit!$A$12:$A$371,Графики!D11,Credit!$D$12:$D$371) -> 9187500 | K11: =SUMIF(Credit!$A$12:$A$371,Графики!D11,Credit!$C$12:$C$371) -> 37500000
B12: =B11+1 -> 6 | C12: =MONTH(D12) -> 12 | D12: =EDATE(D11,1) -> 46357 | F12: =$F$3*8% -> 15772219 | J12: =SUMIF(Credit!$A$12:$A$371,Графики!D12,Credit!$D$12:$D$371) -> 8531250 | K12: =SUMIF(Credit!$A$12:$A$371,Графики!D12,Credit!$C$12:$C$371) -> 37500000
B13: =B12+1 -> 7 | C13: =MONTH(D13) -> 1 | D13: =EDATE(D12,1) -> 46388 | F13: =$F$3*8% -> 15772219 | J13: =SUMIF(Credit!$A$12:$A$371,Графики!D13,Credit!$D$12:$D$371) -> 7875000 | K13: =SUMIF(Credit!$A$12:$A$371,Графики!D13,Credit!$C$12:$C$371) -> 37500000
B14: =B13+1 -> 8 | C14: =MONTH(D14) -> 2 | D14: =EDATE(D13,1) -> 46419 | F14: =$F$3*8% -> 15772219 | I14: =$I$3*5% -> 34385573 | J14: =SUMIF(Credit!$A$12:$A$371,Графики!D14,Credit!$D$12:$D$371) -> 7218750 | K14: =SUMIF(Credit!$A$12:$A$371,Графики!D14,Credit!$C$12:$C$371) -> 37500000
B15: =B14+1 -> 9 | C15: =MONTH(D15) -> 3 | D15: =EDATE(D14,1) -> 46447 | F15: =$F$3*8% -> 15772219 | J15: =SUMIF(Credit!$A$12:$A$371,Графики!D15,Credit!$D$12:$D$371) -> 6562500 | K15: =SUMIF(Credit!$A$12:$A$371,Графики!D15,Credit!$C$12:$C$371) -> 37500000 | M15: =100/12 -> 8.3333333
B16: =B15+1 -> 10 | C16: =MONTH(D16) -> 4 | D16: =EDATE(D15,1) -> 46478 | F16: =$F$3*8% -> 15772219 | J16: =SUMIF(Credit!$A$12:$A$371,Графики!D16,Credit!$D$12:$D$371) -> 5906250 | K16: =SUMIF(Credit!$A$12:$A$371,Графики!D16,Credit!$C$12:$C$371) -> 37500000
B17: =B16+1 -> 11 | C17: =MONTH(D17) -> 5 | D17: =EDATE(D16,1) -> 46508 | F17: =$F$3*8% -> 15772219 | H17: =$H$3*20% -> 1.2831612e+08 | I17: =$I$3*5% -> 34385573 | J17: =SUMIF(Credit!$A$12:$A$371,Графики!D17,Credit!$D$12:$D$371) -> 5250000 | K17: =SUMIF(Credit!$A$12:$A$371,Графики!D17,Credit!$C$12:$C$371) -> 37500000 | M17: =8*11 -> 88
B18: =B17+1 -> 12 | C18: =MONTH(D18) -> 6 | D18: =EDATE(D17,1) -> 46539 | F18: =$F$3*12% -> 23658329 | J18: =SUMIF(Credit!$A$12:$A$371,Графики!D18,Credit!$D$12:$D$371) -> 4593750 | K18: =SUMIF(Credit!$A$12:$A$371,Графики!D18,Credit!$C$12:$C$371) -> 37500000
B19: =B18+1 -> 13 | C19: =MONTH(D19) -> 7 | D19: =EDATE(D18,1) -> 46569 | J19: =SUMIF(Credit!$A$12:$A$371,Графики!D19,Credit!$D$12:$D$371) -> 3937500 | K19: =SUMIF(Credit!$A$12:$A$371,Графики!D19,Credit!$C$12:$C$371) -> 37500000
B20: =B19+1 -> 14 | C20: =MONTH(D20) -> 8 | D20: =EDATE(D19,1) -> 46600 | I20: =$I$3*5% -> 34385573 | J20: =SUMIF(Credit!$A$12:$A$371,Графики!D20,Credit!$D$12:$D$371) -> 3281250 | K20: =SUMIF(Credit!$A$12:$A$371,Графики!D20,Credit!$C$12:$C$371) -> 37500000
B21: =B20+1 -> 15 | C21: =MONTH(D21) -> 9 | D21: =EDATE(D20,1) -> 46631 | J21: =SUMIF(Credit!$A$12:$A$371,Графики!D21,Credit!$D$12:$D$371) -> 2625000 | K21: =SUMIF(Credit!$A$12:$A$371,Графики!D21,Credit!$C$12:$C$371) -> 37500000
B22: =B21+1 -> 16 | C22: =MONTH(D22) -> 10 | D22: =EDATE(D21,1) -> 46661 | J22: =SUMIF(Credit!$A$12:$A$371,Графики!D22,Credit!$D$12:$D$371) -> 1968750 | K22: =SUMIF(Credit!$A$12:$A$371,Графики!D22,Credit!$C$12:$C$371) -> 37500000
B23: =B22+1 -> 17 | C23: =MONTH(D23) -> 11 | D23: =EDATE(D22,1) -> 46692 | I23: =$I$3*5% -> 34385573 | J23: =SUMIF(Credit!$A$12:$A$371,Графики!D23,Credit!$D$12:$D$371) -> 1312500 | K23: =SUMIF(Credit!$A$12:$A$371,Графики!D23,Credit!$C$12:$C$371) -> 37500000
B24: =B23+1 -> 18 | C24: =MONTH(D24) -> 12 | D24: =EDATE(D23,1) -> 46722 | J24: =SUMIF(Credit!$A$12:$A$371,Графики!D24,Credit!$D$12:$D$371) -> 656250 | K24: =SUMIF(Credit!$A$12:$A$371,Графики!D24,Credit!$C$12:$C$371) -> 37500000
B25: =B24+1 -> 19 | C25: =MONTH(D25) -> 1 | D25: =EDATE(D24,1) -> 46753 | J25: =SUMIF(Credit!$A$12:$A$371,Графики!D25,Credit!$D$12:$D$371) -> 0 | K25: =SUMIF(Credit!$A$12:$A$371,Графики!D25,Credit!$C$12:$C$371) -> 0
B26: =B25+1 -> 20 | C26: =MONTH(D26) -> 2 | D26: =EDATE(D25,1) -> 46784 | E26: =$E$3*100% -> 675000000 | I26: =$I$3*75% -> 5.1578359e+08 | J26: =SUMIF(Credit!$A$12:$A$371,Графики!D26,Credit!$D$12:$D$371) -> 0 | K26: =SUMIF(Credit!$A$12:$A$371,Графики!D26,Credit!$C$12:$C$371) -> 0
B27: =B26+1 -> 21 | C27: =MONTH(D27) -> 3 | D27: =EDATE(D26,1) -> 46813 | J27: =SUMIF(Credit!$A$12:$A$371,Графики!D27,Credit!$D$12:$D$371) -> 0 | K27: =SUMIF(Credit!$A$12:$A$371,Графики!D27,Credit!$C$12:$C$371) -> 0
B28: =B27+1 -> 22 | C28: =MONTH(D28) -> 4 | D28: =EDATE(D27,1) -> 46844 | J28: =SUMIF(Credit!$A$12:$A$371,Графики!D28,Credit!$D$12:$D$371) -> 0 | K28: =SUMIF(Credit!$A$12:$A$371,Графики!D28,Credit!$C$12:$C$371) -> 0
B29: =B28+1 -> 23 | C29: =MONTH(D29) -> 5 | D29: =EDATE(D28,1) -> 46874 | H29: =$H$3*80% -> 5.1326448e+08 | J29: =SUMIF(Credit!$A$12:$A$371,Графики!D29,Credit!$D$12:$D$371) -> 0 | K29: =SUMIF(Credit!$A$12:$A$371,Графики!D29,Credit!$C$12:$C$371) -> 0
B30: =B29+1 -> 24 | C30: =MONTH(D30) -> 6 | D30: =EDATE(D29,1) -> 46905 | G30: =$G$3/24 -> 0 | J30: =SUMIF(Credit!$A$12:$A$371,Графики!D30,Credit!$D$12:$D$371) -> 0 | K30: =SUMIF(Credit!$A$12:$A$371,Графики!D30,Credit!$C$12:$C$371) -> 0
B31: =B30+1 -> 25 | C31: =MONTH(D31) -> 7 | D31: =EDATE(D30,1) -> 46935 | G31: =$G$3/24 -> 0 | J31: =SUMIF(Credit!$A$12:$A$371,Графики!D31,Credit!$D$12:$D$371) -> 0 | K31: =SUMIF(Credit!$A$12:$A$371,Графики!D31,Credit!$C$12:$C$371) -> 0
B32: =B31+1 -> 26 | C32: =MONTH(D32) -> 8 | D32: =EDATE(D31,1) -> 46966 | G32: =$G$3/24 -> 0 | J32: =SUMIF(Credit!$A$12:$A$371,Графики!D32,Credit!$D$12:$D$371) -> 0 | K32: =SUMIF(Credit!$A$12:$A$371,Графики!D32,Credit!$C$12:$C$371) -> 0
B33: =B32+1 -> 27 | C33: =MONTH(D33) -> 9 | D33: =EDATE(D32,1) -> 46997 | G33: =$G$3/24 -> 0 | J33: =SUMIF(Credit!$A$12:$A$371,Графики!D33,Credit!$D$12:$D$371) -> 0 | K33: =SUMIF(Credit!$A$12:$A$371,Графики!D33,Credit!$C$12:$C$371) -> 0
B34: =B33+1 -> 28 | C34: =MONTH(D34) -> 10 | D34: =EDATE(D33,1) -> 47027 | G34: =$G$3/24 -> 0 | J34: =SUMIF(Credit!$A$12:$A$371,Графики!D34,Credit!$D$12:$D$371) -> 0 | K34: =SUMIF(Credit!$A$12:$A$371,Графики!D34,Credit!$C$12:$C$371) -> 0
B35: =B34+1 -> 29 | C35: =MONTH(D35) -> 11 | D35: =EDATE(D34,1) -> 47058 | G35: =$G$3/24 -> 0 | J35: =SUMIF(Credit!$A$12:$A$371,Графики!D35,Credit!$D$12:$D$371) -> 0 | K35: =SUMIF(Credit!$A$12:$A$371,Графики!D35,Credit!$C$12:$C$371) -> 0
B36: =B35+1 -> 30 | C36: =MONTH(D36) -> 12 | D36: =EDATE(D35,1) -> 47088 | G36: =$G$3/24 -> 0 | J36: =SUMIF(Credit!$A$12:$A$371,Графики!D36,Credit!$D$12:$D$371) -> 0 | K36: =SUMIF(Credit!$A$12:$A$371,Графики!D36,Credit!$C$12:$C$371) -> 0 | M36: =100/6 -> 16.666667
B37: =B36+1 -> 31 | C37: =MONTH(D37) -> 1 | D37: =EDATE(D36,1) -> 47119 | G37: =$G$3/24 -> 0 | J37: =SUMIF(Credit!$A$12:$A$371,Графики!D37,Credit!$D$12:$D$371) -> 0 | K37: =SUMIF(Credit!$A$12:$A$371,Графики!D37,Credit!$C$12:$C$371) -> 0 | M37: 16.666667
B38: =B37+1 -> 32 | C38: =MONTH(D38) -> 2 | D38: =EDATE(D37,1) -> 47150 | G38: =$G$3/24 -> 0 | J38: =SUMIF(Credit!$A$12:$A$371,Графики!D38,Credit!$D$12:$D$371) -> 0 | K38: =SUMIF(Credit!$A$12:$A$371,Графики!D38,Credit!$C$12:$C$371) -> 0
B39: =B38+1 -> 33 | C39: =MONTH(D39) -> 3 | D39: =EDATE(D38,1) -> 47178 | G39: =$G$3/24 -> 0 | J39: =SUMIF(Credit!$A$12:$A$371,Графики!D39,Credit!$D$12:$D$371) -> 0 | K39: =SUMIF(Credit!$A$12:$A$371,Графики!D39,Credit!$C$12:$C$371) -> 0
B40: =B39+1 -> 34 | C40: =MONTH(D40) -> 4 | D40: =EDATE(D39,1) -> 47209 | G40: =$G$3/24 -> 0 | J40: =SUMIF(Credit!$A$12:$A$371,Графики!D40,Credit!$D$12:$D$371) -> 0 | K40: =SUMIF(Credit!$A$12:$A$371,Графики!D40,Credit!$C$12:$C$371) -> 0 | M40: =16*5 -> 80
B41: =B40+1 -> 35 | C41: =MONTH(D41) -> 5 | D41: =EDATE(D40,1) -> 47239 | G41: =$G$3/24 -> 0 | J41: =SUMIF(Credit!$A$12:$A$371,Графики!D41,Credit!$D$12:$D$371) -> 0 | K41: =SUMIF(Credit!$A$12:$A$371,Графики!D41,Credit!$C$12:$C$371) -> 0
B42: =B41+1 -> 36 | C42: =MONTH(D42) -> 6 | D42: =EDATE(D41,1) -> 47270 | G42: =$G$3/24 -> 0 | J42: =SUMIF(Credit!$A$12:$A$371,Графики!D42,Credit!$D$12:$D$371) -> 0 | K42: =SUMIF(Credit!$A$12:$A$371,Графики!D42,Credit!$C$12:$C$371) -> 0
...

Sheet НДС расчет
B2: Себестоимость без НДС | C2: =C3/1.16 -> 4.9374068e+09
B3: Себестоимость с НДС | C3: ='PnL все'!B40+'PnL все'!B50+'PnL все'!B53+'PnL все'!B61 -> 5727391923
B4: НДС к зачету входящий | C4: =C3-C2 -> 7.8998509e+08
B5: Выручка без НДС | C5: ='PnL все'!B34/1.16 -> 9.2356034e+09
B6: Выручка с НДС | C6: ='PnL все'!B34 -> 10713300000
B7: Исходящий НДС (начисленный) | C7: =C6-C5 -> 1.4776966e+09
B8: НДС к уплате в бюджет | C8: =C7-C4 -> 6.8771146e+08

Sheet Sales
I1: Months
C2: Реализуемая площадь | D2: ='Dashboard все'!C25 -> 6901 | I2: 1-4 | J2: 0.03 | K2: 4 | L2: =J2*K2 -> 0.12
C3: Площадь одной очереди | D3: ='Dashboard все'!C26 -> 6901 | I3: 5-8 | J3: 0.031 | K3: =8-5+1 -> 4 | L3: =J3*K3 -> 0.124
C4: Количество очередей | D4: 1 | I4: 9-13 | J4: 0.032 | K4: =13-9+1 -> 5 | L4: =J4*K4 -> 0.16
C5: Итого продажи | D5: ='PnL все'!B34 -> 10713300000 | I5: 14-18 | J5: 0.033 | K5: =18-14+1 -> 5 | L5: =J5*K5 -> 0.165
C6: Продажи на 1 очередь | D6: =D5/D4 -> 10713300000 | I6: 19-24 | J6: =L6/K6 -> 0.071833333 | K6: =24-19+1 -> 6 | L6: =L10-L2-L3-L4-L5 -> 0.431
I7: 25-29 | J7: 0.036 | K7: =29-25+1 -> 5
I8: 30-33 | K8: =33-30+1 -> 4
D9: =D6-B14 -> 0
I10: Total | J10: 0.01 | K10: =SUM(K2:K9) -> 33 | L10: 1
